<sdf version='1.7'>
  <model name='iBot'>
    <link name='robot_footprint'>
      <inertial>
        <pose>0.001151 0 -0.150164 0 -0 0</pose>
        <mass>15.2</mass>
        <inertia>
          <ixx>0.0626454</ixx>
          <ixy>4.24915e-17</ixy>
          <ixz>0.000434622</ixz>
          <iyy>0.215688</iyy>
          <iyz>1.50945e-32</iyz>
          <izz>0.253126</izz>
        </inertia>
      </inertial>
      <collision name='robot_footprint_fixed_joint_lump__collision_collision'>
        <pose>0 0 -0.15 0 -0 0</pose>
        <geometry>
          <box>
            <size>0.4 0.2 0.1</size>
          </box>
        </geometry>
      </collision>
      <collision name='robot_footprint_fixed_joint_lump__camera_colision_collision_1'>
        <pose>0.175 0 -0.175 0 1.5708 0</pose>
        <geometry>
          <box>
            <size>0.05 0.05 0.05</size>
          </box>
        </geometry>
      </collision>
      <collision name='robot_footprint_fixed_joint_lump__imu_colision_collision_2'>
        <pose>0 0 -0.15 0 -0 0</pose>
        <geometry>
          <box>
            <size>0.05 0.05 0.05</size>
          </box>
        </geometry>
      </collision>
      <visual name='robot_footprint_fixed_joint_lump__chassis_visual_visual'>
        <pose>0 0 -0.15 1.5708 -0 0</pose>
        <geometry>
          <mesh>
            <scale>1 1 1</scale>
            <uri>model://iBot/meshes/chassis3.obj</uri>
          </mesh>
        </geometry>
      </visual>
      <visual name='robot_footprint_fixed_joint_lump__camera_visual_visual_1'>
        <pose>0.175 0 -0.175 1.5707 0 1.5708</pose>
        <geometry>
          <mesh>
            <scale>1 1 1</scale>
            <uri>model://iBot/meshes/camera.obj</uri>
          </mesh>
        </geometry>
      </visual>
      <visual name='robot_footprint_fixed_joint_lump__imu_visual_visual_2'>
        <pose>0 0 -0.15 0 -0 0</pose>
        <geometry>
          <box>
            <size>0.05 0.05 0.05</size>
          </box>
        </geometry>
        <material>
          <script>
            <name>Gazebo/Red</name>
            <uri>file://media/materials/scripts/gazebo.material</uri>
          </script>
        </material>
      </visual>
      <velocity_decay/>
      <sensor name='camera_sensor' type='camera'>
        <update_rate>30</update_rate>
        <always_on>1</always_on>
        <camera name='camera'>
          <horizontal_fov>1.39626</horizontal_fov>
          <image>
            <width>800</width>
            <height>800</height>
            <format>R8G8B8</format>
          </image>
          <clip>
            <near>0.02</near>
            <far>300</far>
          </clip>
          <distortion>
            <k1>0</k1>
            <k2>0</k2>
            <k3>0</k3>
            <p1>0</p1>
            <p2>0</p2>
            <center>0.5 0.5</center>
          </distortion>
        </camera>
        <plugin name='camera_controller' filename='libgazebo_ros_camera.so'>
          <ros>
            <namespace>/iBot</namespace>
            <remapping>camera/image_raw:=/iBot/camera/image</remapping>
            <remapping>camera/camera_info:=/iBot/camera/image/camera_info</remapping>
          </ros>
          <camera_name>camera</camera_name>
          <frame_name>camera</frame_name>
          <hack_baseline>0.07</hack_baseline>
        </plugin>
        <pose>0.175 0 -0.175 3.14159 1.57079 3.14159</pose>
      </sensor>
      <velocity_decay/>
      <sensor name='imu_sensor' type='imu'>
        <plugin name='imu' filename='libgazebo_ros_imu_sensor.so'>
          <ros>
            <namespace>/iBot</namespace>
            <remapping>~/out:=imu</remapping>
          </ros>
          <initial_orientation_as_reference>0</initial_orientation_as_reference>
        </plugin>
        <always_on>1</always_on>
        <update_rate>100</update_rate>
        <visualize>1</visualize>
        <imu>
          <angular_velocity>
            <x>
              <noise type='gaussian'>
                <mean>0</mean>
                <stddev>0.0002</stddev>
                <bias_mean>7.5e-06</bias_mean>
                <bias_stddev>8e-07</bias_stddev>
              </noise>
            </x>
            <y>
              <noise type='gaussian'>
                <mean>0</mean>
                <stddev>0.0002</stddev>
                <bias_mean>7.5e-06</bias_mean>
                <bias_stddev>8e-07</bias_stddev>
              </noise>
            </y>
            <z>
              <noise type='gaussian'>
                <mean>0</mean>
                <stddev>0.0002</stddev>
                <bias_mean>7.5e-06</bias_mean>
                <bias_stddev>8e-07</bias_stddev>
              </noise>
            </z>
          </angular_velocity>
          <linear_acceleration>
            <x>
              <noise type='gaussian'>
                <mean>0</mean>
                <stddev>0.017</stddev>
                <bias_mean>0.1</bias_mean>
                <bias_stddev>0.001</bias_stddev>
              </noise>
            </x>
            <y>
              <noise type='gaussian'>
                <mean>0</mean>
                <stddev>0.017</stddev>
                <bias_mean>0.1</bias_mean>
                <bias_stddev>0.001</bias_stddev>
              </noise>
            </y>
            <z>
              <noise type='gaussian'>
                <mean>0</mean>
                <stddev>0.017</stddev>
                <bias_mean>0.1</bias_mean>
                <bias_stddev>0.001</bias_stddev>
              </noise>
            </z>
          </linear_acceleration>
        </imu>
        <pose>0 0 -0.15 0 -0 0</pose>
      </sensor>
      <gravity>1</gravity>
      <velocity_decay/>
    </link>
    <joint name='back_left_wheel_joint' type='revolute'>
      <pose relative_to='robot_footprint'>-0.175 0.16 -0.175 0 -0 0</pose>
      <parent>robot_footprint</parent>
      <child>back_left_wheel_link</child>
      <axis>
        <xyz>0 1 0</xyz>
        <limit>
          <lower>-1e+16</lower>
          <upper>1e+16</upper>
          <effort>1000</effort>
          <velocity>1000</velocity>
        </limit>
        <dynamics>
          <damping>1</damping>
          <friction>1</friction>
          <spring_reference>0</spring_reference>
          <spring_stiffness>0</spring_stiffness>
        </dynamics>
      </axis>
    </joint>
    <link name='back_left_wheel_link'>
      <pose relative_to='back_left_wheel_joint'>0 0 0 0 -0 0</pose>
      <inertial>
        <pose>0 0 0 1.5708 -0 0</pose>
        <mass>5</mass>
        <inertia>
          <ixx>0.0236979</ixx>
          <ixy>0</ixy>
          <ixz>0</ixz>
          <iyy>0.0236979</iyy>
          <iyz>0</iyz>
          <izz>0.0390625</izz>
        </inertia>
      </inertial>
      <collision name='back_left_wheel_link_collision'>
        <pose>0 0 0 1.5708 -0 0</pose>
        <geometry>
          <cylinder>
            <length>0.1</length>
            <radius>0.125</radius>
          </cylinder>
        </geometry>
      </collision>
      <visual name='back_left_wheel_link_visual'>
        <pose>0 0 0 1.5708 -0 0</pose>
        <geometry>
          <mesh>
            <scale>1 1 1</scale>
            <uri>model://iBot/meshes/wheel3.obj</uri>
          </mesh>
        </geometry>
      </visual>
    </link>
    <joint name='back_right_wheel_joint' type='revolute'>
      <pose relative_to='robot_footprint'>-0.175 -0.16 -0.175 0 -0 0</pose>
      <parent>robot_footprint</parent>
      <child>back_right_wheel_link</child>
      <axis>
        <xyz>0 1 0</xyz>
        <limit>
          <lower>-1e+16</lower>
          <upper>1e+16</upper>
          <effort>1000</effort>
          <velocity>1000</velocity>
        </limit>
        <dynamics>
          <damping>1</damping>
          <friction>1</friction>
          <spring_reference>0</spring_reference>
          <spring_stiffness>0</spring_stiffness>
        </dynamics>
      </axis>
    </joint>
    <link name='back_right_wheel_link'>
      <pose relative_to='back_right_wheel_joint'>0 0 0 0 -0 0</pose>
      <inertial>
        <pose>0 0 0 1.5708 -0 0</pose>
        <mass>5</mass>
        <inertia>
          <ixx>0.0236979</ixx>
          <ixy>0</ixy>
          <ixz>0</ixz>
          <iyy>0.0236979</iyy>
          <iyz>0</iyz>
          <izz>0.0390625</izz>
        </inertia>
      </inertial>
      <collision name='back_right_wheel_link_collision'>
        <pose>0 0 0 1.5708 -0 0</pose>
        <geometry>
          <cylinder>
            <length>0.1</length>
            <radius>0.125</radius>
          </cylinder>
        </geometry>
      </collision>
      <visual name='back_right_wheel_link_visual'>
        <pose>0 0 0 1.5708 -0 0</pose>
        <geometry>
          <mesh>
            <scale>1 1 1</scale>
            <uri>model://iBot/meshes/wheel3.obj</uri>
          </mesh>
        </geometry>
      </visual>
    </link>
    <joint name='front_left_wheel_joint' type='revolute'>
      <pose relative_to='robot_footprint'>0.175 0.16 -0.175 0 -0 0</pose>
      <parent>robot_footprint</parent>
      <child>front_left_wheel_link</child>
      <axis>
        <xyz>0 1 0</xyz>
        <limit>
          <lower>-1e+16</lower>
          <upper>1e+16</upper>
          <effort>1000</effort>
          <velocity>1000</velocity>
        </limit>
        <dynamics>
          <damping>1</damping>
          <friction>1</friction>
          <spring_reference>0</spring_reference>
          <spring_stiffness>0</spring_stiffness>
        </dynamics>
      </axis>
    </joint>
    <link name='front_left_wheel_link'>
      <pose relative_to='front_left_wheel_joint'>0 0 0 0 -0 0</pose>
      <inertial>
        <pose>0 0 0 1.5708 -0 0</pose>
        <mass>5</mass>
        <inertia>
          <ixx>0.0236979</ixx>
          <ixy>0</ixy>
          <ixz>0</ixz>
          <iyy>0.0236979</iyy>
          <iyz>0</iyz>
          <izz>0.0390625</izz>
        </inertia>
      </inertial>
      <collision name='front_left_wheel_link_collision'>
        <pose>0 0 0 1.5708 -0 0</pose>
        <geometry>
          <cylinder>
            <length>0.1</length>
            <radius>0.125</radius>
          </cylinder>
        </geometry>
      </collision>
      <visual name='front_left_wheel_link_visual'>
        <pose>0 0 0 1.5708 -0 0</pose>
        <geometry>
          <mesh>
            <scale>1 1 1</scale>
            <uri>model://iBot/meshes/wheel3.obj</uri>
          </mesh>
        </geometry>
      </visual>
    </link>
    <joint name='front_right_wheel_joint' type='revolute'>
      <pose relative_to='robot_footprint'>0.175 -0.16 -0.175 0 -0 0</pose>
      <parent>robot_footprint</parent>
      <child>front_right_wheel_link</child>
      <axis>
        <xyz>0 1 0</xyz>
        <limit>
          <lower>-1e+16</lower>
          <upper>1e+16</upper>
          <effort>1000</effort>
          <velocity>1000</velocity>
        </limit>
        <dynamics>
          <damping>1</damping>
          <friction>1</friction>
          <spring_reference>0</spring_reference>
          <spring_stiffness>0</spring_stiffness>
        </dynamics>
      </axis>
    </joint>
    <link name='front_right_wheel_link'>
      <pose relative_to='front_right_wheel_joint'>0 0 0 0 -0 0</pose>
      <inertial>
        <pose>0 0 0 1.5708 -0 0</pose>
        <mass>5</mass>
        <inertia>
          <ixx>0.0236979</ixx>
          <ixy>0</ixy>
          <ixz>0</ixz>
          <iyy>0.0236979</iyy>
          <iyz>0</iyz>
          <izz>0.0390625</izz>
        </inertia>
      </inertial>
      <collision name='front_right_wheel_link_collision'>
        <pose>0 0 0 1.5708 -0 0</pose>
        <geometry>
          <cylinder>
            <length>0.1</length>
            <radius>0.125</radius>
          </cylinder>
        </geometry>
      </collision>
      <visual name='front_right_wheel_link_visual'>
        <pose>0 0 0 1.5708 -0 0</pose>
        <geometry>
          <mesh>
            <scale>1 1 1</scale>
            <uri>model://iBot/meshes/wheel3.obj</uri>
          </mesh>
        </geometry>
      </visual>
    </link>
    <plugin name='differential_drive_controller' filename='libgazebo_ros_diff_drive.so'>
      <ros>
        <namespace>iBot</namespace>
        <remapping>/cmd_vel:=cmd_vel</remapping>
        <remapping>/odom:=odom</remapping>
      </ros>
      <update_rate>100.0</update_rate>
      <num_wheel_pairs>2</num_wheel_pairs>
      <odometry_frame>odom</odometry_frame>
      <left_joint>front_left_wheel_joint</left_joint>
      <left_joint>back_left_wheel_joint</left_joint>
      <wheel_separation>0.32</wheel_separation>
      <wheel_diameter>0.25</wheel_diameter>
      <right_joint>front_right_wheel_joint</right_joint>
      <right_joint>back_right_wheel_joint</right_joint>
      <wheel_separation>0.32</wheel_separation>
      <wheel_diameter>0.25</wheel_diameter>
      <max_wheel_torque>20</max_wheel_torque>
      <max_wheel_acceleration>1.0</max_wheel_acceleration>
      <publish_odom>1</publish_odom>
      <publish_odom_tf>0</publish_odom_tf>
      <publish_wheel_tf>0</publish_wheel_tf>
      <odometry_frame>odom</odometry_frame>
      <robot_base_frame>robot_footprint</robot_base_frame>
      <odometry_source>world</odometry_source>
    </plugin>
    <plugin name='joint_state_publisher' filename='libgazebo_ros_joint_state_publisher.so'>
      <ros>
        <namespace>iBot</namespace>
        <remapping>~/out:=joint_states</remapping>
      </ros>
      <update_rate>30</update_rate>
      <joint_name>front_left_wheel_joint</joint_name>
      <joint_name>front_right_wheel_joint</joint_name>
      <joint_name>back_left_wheel_joint</joint_name>
      <joint_name>back_right_wheel_joint</joint_name>
    </plugin>
    <static>0</static>
    <plugin name='gazebo_ros_force' filename='libgazebo_ros_force.so'>
      <ros>
        <namespace>iBot</namespace>
        <remapping>/gazebo_ros_force:=wrench</remapping>
      </ros>
      <update_rate>100</update_rate>
      <always_on>1</always_on>
      <link_name>robot_footprint</link_name>
      <force_frame>link</force_frame>
    </plugin>
  </model>
</sdf>
