<?xml version="1.0"?>
<sdf version='1.5'>
  <model name='iBot'>
    <static>false</static>
    <link name='robot_footprint'>
      <inertial>
        <pose>0.001656 0.000331 0.000331 0 -0 0</pose>
        <mass>15.1</mass>
        <inertia>
          <ixx>0.100499</ixx>
          <ixy>-0.00124172</ixy>
          <ixz>-0.00124187</ixz>
          <iyy>0.106459</iyy>
          <iyz>-0.000248344</iyz>
          <izz>0.106459</izz>
        </inertia>
      </inertial>
      <collision name='robot_footprint_fixed_joint_lump__collision_collision'>
        <pose>0 0 0 0 -0 0</pose>
        <geometry>
          <box>
            <size>0.4 0.2 0.1</size>
          </box>
        </geometry>
      </collision>
      <collision name='robot_footprint_fixed_joint_lump__camera_colision_collision_1'>
        <pose>0.2 0 0 0 -0 0</pose>
        <geometry>
          <box>
            <size>0.05 0.05 0.05</size>
          </box>
        </geometry>
      </collision>
      <collision name='robot_footprint_fixed_joint_lump__hokuyo_colision_collision_2'>
        <pose>0.15 0 0.1 0 -0 0</pose>
        <geometry>
          <box>
            <size>0.1 0.1 0.1</size>
          </box>
        </geometry>
      </collision>
      <visual name='robot_footprint_fixed_joint_lump__chassis_visual_visual'>
        <pose>0 0 0 0 -0 0</pose>
        <geometry>
          <box>
            <size>0.4 0.2 0.1</size>
          </box>
        </geometry>
        <material>
          <script>
            <name>Gazebo/Blue</name>
            <uri>file://media/materials/scripts/gazebo.material</uri>
          </script>
        </material>
      </visual>
      <visual name='robot_footprint_fixed_joint_lump__camera_visual_visual_1'>
        <pose>0.2 0 0 0 -0 0</pose>
        <geometry>
          <box>
            <size>0.05 0.05 0.05</size>
          </box>
        </geometry>
        <material>
          <script>
            <name>Gazebo/Red</name>
            <uri>file://media/materials/scripts/gazebo.material</uri>
          </script>
        </material>
      </visual>
      <visual name='robot_footprint_fixed_joint_lump__hokuyo_visual_visual_2'>
        <pose>0.15 0 0.1 0 -0 0</pose>
        <geometry>
          <box>
            <size>0.05 0.05 0.05</size>
          </box>
        </geometry>
        <material>
          <script>
            <name>Gazebo/Black</name>
            <uri>file://media/materials/scripts/gazebo.material</uri>
          </script>
        </material>
      </visual>
      <velocity_decay/>
      <velocity_decay/>
      <sensor name='camera_sensor' type='camera'>
        <update_rate>30</update_rate>
        <always_on>1</always_on>
        <camera name='camera'>
          <horizontal_fov>1.39626</horizontal_fov>
          <image>
            <width>800</width>
            <height>800</height>
            <format>R8G8B8</format>
          </image>
          <clip>
            <near>0.02</near>
            <far>300</far>
          </clip>
          <distortion>
            <k1>0</k1>
            <k2>0</k2>
            <k3>0</k3>
            <p1>0</p1>
            <p2>0</p2>
            <center>0.5 0.5</center>
          </distortion>
        </camera>
        <plugin name='camera_controller' filename='libgazebo_ros_camera.so'>
          <ros>
            <namespace>/iBot</namespace>
            <argument>camera/image_raw:=/iBot/camera/image</argument>
            <argument>camera/camera_info:=/iBot/camera/image/camera_info</argument>
          </ros>
          <camera_name>camera</camera_name>
          <frame_name>camera</frame_name>
          <hack_baseline>0.07</hack_baseline>
        </plugin>
        <pose>0.2 0 0 0 -0 0</pose>
      </sensor>
      <velocity_decay/>
      <velocity_decay/>
      <sensor name='head_hokuyo_sensor' type='ray'>
        <visualize>0</visualize>
        <update_rate>40</update_rate>
        <ray>
          <scan>
            <horizontal>
              <samples>720</samples>
              <resolution>1</resolution>
              <min_angle>-1.5708</min_angle>
              <max_angle>1.5708</max_angle>
            </horizontal>
          </scan>
          <range>
            <min>0.1</min>
            <max>30</max>
            <resolution>0.01</resolution>
          </range>
          <noise>
            <type>gaussian</type>
            <mean>0</mean>
            <stddev>0.01</stddev>
          </noise>
        </ray>
        <update_rate>30</update_rate>
        <plugin name='gazebo_ros_head_hokuyo_controller' filename='libgazebo_ros_ray_sensor.so'>
          <ros>
            <namespace>/iBot</namespace>
            <argument>~/out:=scan</argument>
          </ros>
          <output_type>sensor_msgs/LaserScan</output_type>
        </plugin>
        <pose>0.15 0 0.1 0 -0 0</pose>
      </sensor>
      <gravity>1</gravity>
      <velocity_decay/>
    </link>
    <joint name='back_left_wheel_joint' type='revolute'>
      <pose relative_to='robot_footprint'>-0.12 0.15 0 0 -0 0</pose>
      <parent>robot_footprint</parent>
      <child>back_left_wheel</child>
      <axis>
        <xyz>0 1 0</xyz>
        <limit>
          <lower>-1e+16</lower>
          <upper>1e+16</upper>
        </limit>
        <dynamics>
          <damping>1</damping>
          <friction>1</friction>
          <spring_reference>0</spring_reference>
          <spring_stiffness>0</spring_stiffness>
        </dynamics>
      </axis>
    </joint>
    <link name='back_left_wheel'>
      <pose relative_to='back_left_wheel_joint'>0 0 0 0 -0 0</pose>
      <inertial>
        <pose>0 0 0 0 1.5707 1.5707</pose>
        <mass>5</mass>
        <inertia>
          <ixx>0.1</ixx>
          <ixy>0</ixy>
          <ixz>0</ixz>
          <iyy>0.1</iyy>
          <iyz>0</iyz>
          <izz>0.1</izz>
        </inertia>
      </inertial>
      <collision name='back_left_wheel_collision'>
        <pose>0 0 0 -1.5707 1.5708 0</pose>
        <geometry>
          <cylinder>
            <length>0.05</length>
            <radius>0.1</radius>
          </cylinder>
        </geometry>
      </collision>
      <visual name='back_left_wheel_visual'>
        <pose>0 0 0 -1.5707 1.5708 0</pose>
        <geometry>
          <cylinder>
            <length>0.05</length>
            <radius>0.1</radius>
          </cylinder>
        </geometry>
      </visual>
    </link>
    <joint name='back_right_wheel_joint' type='revolute'>
      <pose relative_to='robot_footprint'>-0.12 -0.15 0 0 -0 0</pose>
      <parent>robot_footprint</parent>
      <child>back_right_wheel</child>
      <axis>
        <xyz>0 1 0</xyz>
        <limit>
          <lower>-1e+16</lower>
          <upper>1e+16</upper>
        </limit>
        <dynamics>
          <damping>1</damping>
          <friction>1</friction>
          <spring_reference>0</spring_reference>
          <spring_stiffness>0</spring_stiffness>
        </dynamics>
      </axis>
    </joint>
    <link name='back_right_wheel'>
      <pose relative_to='back_right_wheel_joint'>0 0 0 0 -0 0</pose>
      <inertial>
        <pose>0 0 0 0 1.5707 1.5707</pose>
        <mass>5</mass>
        <inertia>
          <ixx>0.1</ixx>
          <ixy>0</ixy>
          <ixz>0</ixz>
          <iyy>0.1</iyy>
          <iyz>0</iyz>
          <izz>0.1</izz>
        </inertia>
      </inertial>
      <collision name='back_right_wheel_collision'>
        <pose>0 0 0 -1.5707 1.5708 0</pose>
        <geometry>
          <cylinder>
            <length>0.05</length>
            <radius>0.1</radius>
          </cylinder>
        </geometry>
      </collision>
      <visual name='back_right_wheel_visual'>
        <pose>0 0 0 -1.5707 1.5708 0</pose>
        <geometry>
          <cylinder>
            <length>0.05</length>
            <radius>0.1</radius>
          </cylinder>
        </geometry>
      </visual>
    </link>
    <joint name='front_left_wheel_joint' type='revolute'>
      <pose relative_to='robot_footprint'>0.12 0.15 0 0 -0 0</pose>
      <parent>robot_footprint</parent>
      <child>front_left_wheel</child>
      <axis>
        <xyz>0 1 0</xyz>
        <limit>
          <lower>-1e+16</lower>
          <upper>1e+16</upper>
        </limit>
        <dynamics>
          <damping>1</damping>
          <friction>1</friction>
          <spring_reference>0</spring_reference>
          <spring_stiffness>0</spring_stiffness>
        </dynamics>
      </axis>
    </joint>
    <link name='front_left_wheel'>
      <pose relative_to='front_left_wheel_joint'>0 0 0 0 -0 0</pose>
      <inertial>
        <pose>0 0 0 0 1.5707 1.5707</pose>
        <mass>5</mass>
        <inertia>
          <ixx>0.1</ixx>
          <ixy>0</ixy>
          <ixz>0</ixz>
          <iyy>0.1</iyy>
          <iyz>0</iyz>
          <izz>0.1</izz>
        </inertia>
      </inertial>
      <collision name='front_left_wheel_collision'>
        <pose>0 0 0 -1.5707 1.5708 0</pose>
        <geometry>
          <cylinder>
            <length>0.05</length>
            <radius>0.1</radius>
          </cylinder>
        </geometry>
      </collision>
      <visual name='front_left_wheel_visual'>
        <pose>0 0 0 -1.5707 1.5708 0</pose>
        <geometry>
          <cylinder>
            <length>0.05</length>
            <radius>0.1</radius>
          </cylinder>
        </geometry>
      </visual>
    </link>
    <joint name='front_right_wheel_joint' type='revolute'>
      <pose relative_to='robot_footprint'>0.12 -0.15 0 0 -0 0</pose>
      <parent>robot_footprint</parent>
      <child>front_right_wheel</child>
      <axis>
        <xyz>0 1 0</xyz>
        <limit>
          <lower>-1e+16</lower>
          <upper>1e+16</upper>
        </limit>
        <dynamics>
          <damping>1</damping>
          <friction>1</friction>
          <spring_reference>0</spring_reference>
          <spring_stiffness>0</spring_stiffness>
        </dynamics>
      </axis>
    </joint>
    <link name='front_right_wheel'>
      <pose relative_to='front_right_wheel_joint'>0 0 0 0 -0 0</pose>
      <inertial>
        <pose>0 0 0 0 1.5707 1.5707</pose>
        <mass>5</mass>
        <inertia>
          <ixx>0.1</ixx>
          <ixy>0</ixy>
          <ixz>0</ixz>
          <iyy>0.1</iyy>
          <iyz>0</iyz>
          <izz>0.1</izz>
        </inertia>
      </inertial>
      <collision name='front_right_wheel_collision'>
        <pose>0 0 0 -1.5707 1.5708 0</pose>
        <geometry>
          <cylinder>
            <length>0.05</length>
            <radius>0.1</radius>
          </cylinder>
        </geometry>
      </collision>
      <visual name='front_right_wheel_visual'>
        <pose>0 0 0 -1.5707 1.5708 0</pose>
        <geometry>
          <cylinder>
            <length>0.05</length>
            <radius>0.1</radius>
          </cylinder>
        </geometry>
      </visual>
    </link>
    <static>0</static>
    <plugin name='skid_steer_drive_controller' filename='libgazebo_ros_diff_drive.so'>
      <ros>
        <namespace>/iBot</namespace>
        <argument>/cmd_vel:=mr_cme_vel</argument>
        <argument>/odom:=odom</argument>
      </ros>
      <update_rate>100.0</update_rate>
      <num_wheel_pairs>2</num_wheel_pairs>
      <odometry_frame>odom</odometry_frame>
      <left_joint>front_left_wheel_joint</left_joint>
      <left_joint>back_left_wheel_joint</left_joint>
      <wheel_separation>0.4</wheel_separation>
      <wheel_diameter>0.2</wheel_diameter>
      <right_joint>front_right_wheel_joint</right_joint>
      <right_joint>back_right_wheel_joint</right_joint>
      <wheel_separation>0.4</wheel_separation>
      <wheel_diameter>0.2</wheel_diameter>
      <robot_base_frame>robot_footprint</robot_base_frame>
      <max_wheel_torque>20</max_wheel_torque>
      <publish_odom>1</publish_odom>
      <publish_odom_tf>1</publish_odom_tf>
      <publish_wheel_tf>1</publish_wheel_tf>
      <odometry_source>world</odometry_source>
    </plugin>
  </model>
</sdf>
